Workbook

Sheet SD
A1: ID | B1: Name | C1: Age | D1: Overall | E1: Potential | F1: Preferred Foot | G1: Position | H1: Finishing
A2: 158023 | B2: L. Messi | C2: 31 | D2: 94 | E2: 94 | F2: Left | G2: RF | H2: 95
A3: 20801 | B3: Cristiano Ronaldo | C3: 33 | D3: 94 | E3: 94 | F3: Right | G3: ST | H3: 94
A4: 190871 | B4: Neymar Jr | C4: 26 | D4: 92 | E4: 93 | F4: Right | G4: LW | H4: 87
A5: 193080 | B5: De Gea | C5: 27 | D5: 91 | E5: 93 | F5: Right | G5: GK | H5: 13
A6: 192985 | B6: K. De Bruyne | C6: 27 | D6: 91 | E6: 92 | F6: Right | G6: RCM | H6: 82
A7: 183277 | B7: E. Hazard | C7: 27 | D7: 91 | E7: 91 | F7: Right | G7: LF | H7: 84
A8: 177003 | B8: L. ModriÄ‡ | C8: 32 | D8: 91 | E8: 91 | F8: Right | G8: RCM | H8: 72
A9: 176580 | B9: L. SuÃ¡rez | C9: 31 | D9: 91 | E9: 91 | F9: Right | G9: RS | H9: 93
A10: 155862 | B10: Sergio Ramos | C10: 32 | D10: 91 | E10: 91 | F10: Right | G10: RCB | H10: 60
A11: 200389 | B11: J. Oblak | C11: 25 | D11: 90 | E11: 93 | F11: Right | G11: GK | H11: 11
A12: 188545 | B12: R. Lewandowski | C12: 29 | D12: 90 | E12: 90 | F12: Right | G12: ST | H12: 91
A13: 182521 | B13: T. Kroos | C13: 28 | D13: 90 | E13: 90 | F13: Right | G13: LCM | H13: 76
... A500: 190264 | B500: Iago FalquÃ© | C500: 28 | D500: 80 | E500: 80 | F500: Left | G500: RW | H500: 75

Sheet Sheet1
A1: TASK 1 – EXCEL BASED EXPLORATION
A4: Dataset Profile
A5: Dataset | B5: SIZE
A6: Number of records | B6: =COUNTA(SD!$B$2:$B$500) -> 499
A7: Number of columns | B7: =COUNTA(SD!$A$1:$H$1) -> 8
A8: Column names | B8: =_xlfn.TEXTJOIN(", ",TRUE,SD!$A$1:$H$1) -> ID, Name, Age, Overall, Potential, Preferred Foot, Position, Finishing
A11: VALUE RANGE
A12: Field | B12: MIN | C12: MAX | D12: AVG | E12: RANGE
A13: Age | B13: =MIN(SD!$C$2:$C$500) -> 18 | C13: =MAX(SD!$C$2:$C$500) -> 40 | D13: =AVERAGE(SD!$C$2:$C$500) -> 27.192385 | E13: =MAX(SD!$C$2:$C$500)-MIN(SD!$C$2:$C$500) -> 22
A14: Overall | B14: =MIN(SD!$D$2:D500) -> 80 | C14: =MAX(SD!$D$2:$D$500) -> 94 | D14: =AVERAGE(SD!$D$2:$D500) -> 82.905812 | E14: =MAX(SD!$D$2:$D$500)-MIN(SD!$D$2:$D$500) -> 14
A15: Potential | B15: =MIN(SD!$E$2:$E$500) -> 80 | C15: =MAX(SD!$E$2:$E$500) -> 95 | D15: =AVERAGE(SD!$E$2:$E500) -> 84.831663 | E15: =MAX(SD!$E$2:$E$500)-MIN(SD!$E$2:$E$500) -> 15
A16: Finishing | B16: =MIN(SD!$H$2:$H$500) -> 8 | C16: =MAX(SD!$H$2:$H$500) -> 95 | D16: =AVERAGE(SD!$H$2:$H500) -> 59.61523 | E16: =MAX(SD!$H$2:$H$500)-MIN(SD!$H$2:$H$500) -> 87
A18: Count by Preferred Foot
A19: Preferred Foot | B19: Count
A20: Left | B20: =COUNTIF(SD!$F$2:$F$500,"Left") -> 131
A21: Right | B21: =COUNTIF(SD!$F$2:$F$500,"right") -> 368
A22: TOTAL | B22: =COUNTIF(SD!$F$2:$F$500,"Left")+COUNTIF(SD!$F$2:$F$500,"Right") -> 499
A24: Overall Rating Band Distribution
A25: Overall Band | B25: Formula
A26: Below 60 | B26: =COUNTIF(SD!$D:$D,"<60") -> 0
A27: 60–69 | B27: =COUNTIFS(SD!$D:D,">=60",SD!$D:$D,"<=69") -> 0
A28: 70–79 | B28: =COUNTIFS(SD!$D:D,">=70",SD!$D:$D,"<=79") -> 0
A29: 80–89 | B29: =COUNTIFS(SD!$D:$D,">=80",SD!$D:$D,"<=89") -> 485
A30: 90-100 | B30: =COUNTIFS(SD!$D:$D,">=90",SD!$D:$D,"<=100") -> 14
A31: total
A33: Age Band Distribution
A34: Age Band | B34: Formula
A35: Under 20 | B35: =COUNTIF(SD!$C:$C,"<20") -> 4
A36: 20–24 | B36: =COUNTIFS(SD!$C:$C,">=20",SD!$C:$C,"<=24") -> 119
A37: 25–28 | B37: =COUNTIFS(SD!$C:$C,">=25",SD!$C:$C,"<=28") -> 197
A38: 29–32 | B38: =COUNTIFS(SD!$C:$C,">=20",SD!$C:$C,"<=24") -> 119
A39: 33+ | B39: =COUNTIF(SD!$C:$C,">=33") -> 37
A40: TOTAL | B40: =COUNTIF(SD!$C:$C,"<20")+COUNTIFS(SD!$C:$C,">=20",SD!$C:$C,"<=24")+COUNTIFS(SD!$C:$C,">=25",SD!$C:$C,"<=28")+COUNTIFS(SD!$C:$C,">=29",SD!$C:$C,"<=32")+COUNTIF(SD!$C:$C,">=33") -> 499
A42: Count by Position
A43: POSITION | B43: COUNT
A44: CAM | B44: =COUNTIF(SD!$G$2:$G$500,"CAM") -> 32
A45: CB | B45: =COUNTIF(SD!$G$2:$G$500,"CB") -> 29
A46: CDM | B46: =COUNTIF(SD!$G$2:$G$500,"CDM") -> 19
A47: CF | B47: =COUNTIF(SD!$G$2:$G$500,"CF") -> 5
A48: CM | B48: =COUNTIF(SD!$G$2:$G$500,"CM") -> 26
...
